import os
import torch
import torch.nn.functional as F
import torch.nn as nn
import numpy as np
from torch.autograd import Variable
import math
import torch as th
import torch.linalg as la
from torch.nn import Parameter
import torch.linalg as linalg

class Model(torch.nn.Module):

    def __init__(self):
        super().__init__()
        self.conv = torch.nn.Conv2d(64, 32, 3, stride=1, padding=1)

    def forward(self, x):
        v1 = self.conv(x)
        v2 = v1 - 1.5
        return v2



func = Model().to('cpu')


x = torch.randn(1, 64, 128, 128)

test_inputs = [x]

# JIT_STATUS
'''
direct:


jit:
backend='inductor' raised:
CalledProcessError: Command '['/usr/local/bin/gcc', '/tmp/tmpp1wu_e0x/main.c', '-O3', '-shared', '-fPIC', '-Wno-psabi', '-o', '/tmp/tmpp1wu_e0x/cuda_utils.cpython-39-x86_64-linux-gnu.so', '-lcuda', '-L/home/yujunzhe/anaconda3/envs/whitefox/lib/python3.9/site-packages/triton/backends/nvidia/lib', '-L/lib/x86_64-linux-gnu', '-L/lib/i386-linux-gnu', '-I/home/yujunzhe/anaconda3/envs/whitefox/lib/python3.9/site-packages/triton/backends/nvidia/include', '-I/tmp/tmpp1wu_e0x', '-I/home/yujunzhe/anaconda3/envs/whitefox/include/python3.9']' returned non-zero exit status 1.


You can suppress this exception and fall back to eager by setting:
    import torch._dynamo
    torch._dynamo.config.suppress_errors = True

'''